<?xml version="1.0"?>
    <robot name="two_joint_robot">
        <link name="base_link">
            <visual>
                <geometry>
                    <cylinder length="0.1" radius="0.2"/>
                </geometry>
                <material name="blue">
                    <color rgba="0 0 0.8 1"/>
                </material>
            </visual>
            <collision>
                <geometry>
                    <cylinder length="0.1" radius="0.2"/>
                </geometry>
            </collision>
            <inertial>
                <mass value="1"/>
                <inertia ixx="0.1" ixy="0" ixz="0" iyy="0.1" iyz="0" izz="0.1"/>
            </inertial>
        </link>

        <link name="link1">
            <visual>
                <geometry>
                    <box size="0.1 0.1 0.5"/>
                </geometry>
                <origin xyz="0 0 0.25"/>
                <material name="red">
                    <color rgba="0.8 0 0 1"/>
                </material>
            </visual>
            <collision>
                <geometry>
                    <box size="0.1 0.1 0.5"/>
                </geometry>
                <origin xyz="0 0 0.25"/>
            </collision>
            <inertial>
                <mass value="1"/>
                <origin xyz="0 0 0.25"/>
                <inertia ixx="0.1" ixy="0" ixz="0" iyy="0.1" iyz="0" izz="0.01"/>
            </inertial>
        </link>

        <joint name="joint1" type="revolute">
            <parent link="base_link"/>
            <child link="link1"/>
            <origin xyz="0 0 0.05"/>
            <axis xyz="0 0 1"/>
            <limit lower="-3.14" upper="3.14" effort="100" velocity="5"/>
        </joint>

        <link name="link2">
            <visual>
                <geometry>
                    <box size="0.1 0.1 0.5"/>
                </geometry>
                <origin xyz="0 0 0.25"/>
                <material name="green">
                    <color rgba="0 0.8 0 1"/>
                </material>
            </visual>
            <collision>
                <geometry>
                    <box size="0.1 0.1 0.5"/>
                </geometry>
                <origin xyz="0 0 0.25"/>
            </collision>
            <inertial>
                <mass value="1"/>
                <origin xyz="0 0 0.25"/>
                <inertia ixx="0.1" ixy="0" ixz="0" iyy="0.1" iyz="0" izz="0.01"/>
            </inertial>
        </link>

        <joint name="joint2" type="revolute">
            <parent link="link1"/>
            <child link="link2"/>
            <origin xyz="0 0 0.5"/>
            <axis xyz="0 1 0"/>
            <limit lower="-3.14" upper="3.14" effort="100" velocity="5"/>
        </joint>

        <link name="end_effector">
            <visual>
                <geometry>
                    <sphere radius="0.05"/>
                </geometry>
                <material name="white">
                    <color rgba="1 1 1 1"/>
                </material>
            </visual>
            <collision>
                <geometry>
                    <sphere radius="0.05"/>
                </geometry>
            </collision>
            <inertial>
                <mass value="0.1"/>
                <inertia ixx="0.001" ixy="0" ixz="0" iyy="0.001" iyz="0" izz="0.001"/>
            </inertial>
        </link>

        <joint name="joint_end_effector" type="fixed">
            <parent link="link2"/>
            <child link="end_effector"/>
            <origin xyz="0 0 0.5"/>
        </joint>
    </robot>
    
